Workbook
Name NativeTimeline_Order_Date: #N/A
Name Slicer_Loyalty_Card: #N/A
Name Slicer_Roast_Type_Name: #N/A
Name Slicer_Size: #N/A

Sheet Dashboard

Sheet TotalSales
A3: Sum of Sales | C3: Coffee Type Name
A4: Years (Order Date) | B4: Months (Order Date) | C4: Arabica | D4: Excelsa | E4: Liberica | F4: Robusta
A5: 2019 | B5: Jan | C5: 186.855 | D5: 305.97 | E5: 213.16 | F5: 123
B6: Feb | C6: 251.965 | D6: 129.46 | E6: 434.04 | F6: 171.94
B7: Mar | C7: 224.945 | D7: 349.12 | E7: 321.04 | F7: 126.035
B8: Apr | C8: 307.12 | D8: 681.075 | E8: 533.705 | F8: 158.85
B9: May | C9: 53.665 | D9: 83.025 | E9: 193.835 | F9: 68.04
B10: Jun | C10: 163.02 | D10: 678.36 | E10: 171.045 | F10: 372.255
B11: Jul | C11: 345.02 | D11: 273.87 | E11: 184.13 | F11: 201.115
B12: Aug | C12: 334.89 | D12: 70.95 | E12: 134.23 | F12: 166.275
B13: Sep | C13: 178.71 | D13: 166.1 | E13: 439.31 | F13: 492.9
B14: Oct | C14: 301.985 | D14: 153.765 | E14: 215.555 | F14: 213.665
B15: Nov | C15: 312.835 | D15: 63.25 | E15: 350.895 | F15: 96.405
B16: Dec | C16: 265.62 | D16: 526.515 | E16: 187.06 | F16: 210.59
A17: 2020 | B17: Jan | C17: 47.25 | D17: 65.805 | E17: 274.675 | F17: 179.22
B18: Feb | C18: 745.45 | D18: 428.885 | E18: 194.175 | F18: 429.83
B19: Mar | C19: 130.47 | D19: 271.485 | E19: 281.205 | F19: 231.63
B20: Apr | C20: 27 | D20: 347.26 | E20: 147.51 | F20: 240.04
B21: May | C21: 255.115 | D21: 541.73 | E21: 83.43 | F21: 59.08
B22: Jun | C22: 584.79 | D22: 357.43 | E22: 355.34 | F22: 140.88
B23: Jul | C23: 430.62 | D23: 227.425 | E23: 236.315 | F23: 414.585
B24: Aug | C24: 22.5 | D24: 77.72 | E24: 60.5 | F24: 139.68
B25: Sep | C25: 126.15 | D25: 195.11 | E25: 89.13 | F25: 302.66
B26: Oct | C26: 376.03 | D26: 523.24 | E26: 440.965 | F26: 174.47
B27: Nov | C27: 515.18 | D27: 142.56 | E27: 347.04 | F27: 104.085
B28: Dec | C28: 95.86 | D28: 484.76 | E28: 94.17 | F28: 77.105
A29: 2021 | B29: Jan | C29: 258.345 | D29: 139.625 | E29: 279.52 | F29: 160.195
B30: Feb | C30: 342.2 | D30: 284.25 | E30: 251.83 | F30: 80.55
B31: Mar | C31: 418.305 | D31: 468.125 | E31: 405.055 | F31: 253.155
B32: Apr | C32: 102.33 | D32: 242.14 | E32: 554.875 | F32: 106.24
B33: May | C33: 234.72 | D33: 133.08 | E33: 267.2 | F33: 272.69
B34: Jun | C34: 430.39 | D34: 136.205 | E34: 209.6 | F34: 88.335
B35: Jul | C35: 109.005 | D35: 393.575 | E35: 61.035 | F35: 199.49
B36: Aug | C36: 287.525 | D36: 288.67 | E36: 125.58 | F36: 374.135
B37: Sep | C37: 840.93 | D37: 409.875 | E37: 171.33 | F37: 221.44
B38: Oct | C38: 299.07 | D38: 260.325 | E38: 584.64 | F38: 256.365
B39: Nov | C39: 323.325 | D39: 565.57 | E39: 537.81 | F39: 189.475
B40: Dec | C40: 399.485 | D40: 148.2 | E40: 388.22 | F40: 212.075
A41: 2022 | B41: Jan | C41: 112.695 | D41: 166.32 | E41: 843.715 | F41: 146.685
B42: Feb | C42: 114.88 | D42: 133.815 | E42: 91.175 | F42: 53.76
...

Sheet CountryBarChart
A3: Country | B3: Sum of Sales
A4: United Kingdom | B4: 2798.505
A5: Ireland | B5: 6696.865
A6: United States | B6: 35638.885

Sheet Top5Customers
A3: Customer Name | B3: Sum of Sales
A4: Don Flintiff | B4: 278.01
A5: Nealson Cuttler | B5: 281.675
A6: Terri Farra | B6: 289.11
A7: Brenn Dundredge | B7: 307.045
A8: Allis Wilmore | B8: 317.07

Sheet orders
A1: Order ID | B1: Order Date | C1: Customer ID | D1: Product ID | E1: Quantity | F1: Customer Name | G1: Email | H1: Country | I1: Coffee Type | J1: Roast Type | K1: Size | L1: Unit Price | M1: Sales | N1: Coffee Type Name | O1: Roast Type Name | P1: Loyalty Card
A2: O8349 | B2: 2024-01-18 | C2: O8889 | D2: O9079 | E2: 32 | F2: =_xlfn.XLOOKUP(C2,customers!$A$1:$A$1001,customers!$B$1:$B$1001,,0) | G2: =IF(_xlfn.XLOOKUP(C2,customers!$A$1:$A$1001,customers!$C$1:$C$1001,,0)=0,"",_xlfn.XLOOKUP(C2,customers!$A$1:$A$1001,customers!$C$1:$C$1001,,0)) | H2: =_xlfn.XLOOKUP(C2,customers!$A$1:$A$1001,customers!$G$1:$G$1001,,0) | I2: =INDEX(products!$A$1:$G$49,MATCH(orders!$D2,products!$A$1:$A$49,0),MATCH(orders!I$1,products!$A$1:$G$1,0)) | J2: =INDEX(products!$A$1:$G$49,MATCH(orders!$D2,products!$A$1:$A$49,0),MATCH(orders!J$1,products!$A$1:$G$1,0)) | K2: =INDEX(products!$A$1:$G$49,MATCH(orders!$D2,products!$A$1:$A$49,0),MATCH(orders!K$1,products!$A$1:$G$1,0)) | L2: =INDEX(products!$A$1:$G$49,MATCH(orders!$D2,products!$A$1:$A$49,0),MATCH(orders!L$1,products!$A$1:$G$1,0)) | M2: =L2*E2 | N2: =IF(I2="Rob","Robusta",IF(I2="Exc","Excelsa",IF(I2="Ara","Arabica",IF(I2="Lib","Liberica","")))) | O2: =IF(J2="M","Medium",IF(J2="L","Light",IF(J2="D","Dark",""))) | P2: =_xlfn.XLOOKUP(Orders[[#This Row],[Customer ID]],customers!$A$1:$A$1001,customers!$I$1:$I$1001,,0)
A3: O7319 | B3: 2023-07-28 | C3: O5435 | D3: O6541 | E3: 265 | F3: =_xlfn.XLOOKUP(C3,customers!$A$1:$A$1001,customers!$B$1:$B$1001,,0) | G3: =IF(_xlfn.XLOOKUP(C3,customers!$A$1:$A$1001,customers!$C$1:$C$1001,,0)=0,"",_xlfn.XLOOKUP(C3,customers!$A$1:$A$1001,customers!$C$1:$C$1001,,0)) | H3: =_xlfn.XLOOKUP(C3,customers!$A$1:$A$1001,customers!$G$1:$G$1001,,0) | I3: =INDEX(products!$A$1:$G$49,MATCH(orders!$D3,products!$A$1:$A$49,0),MATCH(orders!I$1,products!$A$1:$G$1,0)) | J3: =INDEX(products!$A$1:$G$49,MATCH(orders!$D3,products!$A$1:$A$49,0),MATCH(orders!J$1,products!$A$1:$G$1,0)) | K3: =INDEX(products!$A$1:$G$49,MATCH(orders!$D3,products!$A$1:$A$49,0),MATCH(orders!K$1,products!$A$1:$G$1,0)) | L3: =INDEX(products!$A$1:$G$49,MATCH(orders!$D3,products!$A$1:$A$49,0),MATCH(orders!L$1,products!$A$1:$G$1,0)) | M3: =L3*E3 | N3: =IF(I3="Rob","Robusta",IF(I3="Exc","Excelsa",IF(I3="Ara","Arabica",IF(I3="Lib","Liberica","")))) | O3: =IF(J3="M","Medium",IF(J3="L","Light",IF(J3="D","Dark",""))) | P3: =_xlfn.XLOOKUP(Orders[[#This Row],[Customer ID]],customers!$A$1:$A$1001,customers!$I$1:$I$1001,,0)
A4: O6076 | B4: 2023-08-20 | C4: O1551 | D4: O7841 | E4: 15 | F4: =_xlfn.XLOOKUP(C4,customers!$A$1:$A$1001,customers!$B$1:$B$1001,,0) | G4: =IF(_xlfn.XLOOKUP(C4,customers!$A$1:$A$1001,customers!$C$1:$C$1001,,0)=0,"",_xlfn.XLOOKUP(C4,customers!$A$1:$A$1001,customers!$C$1:$C$1001,,0)) | H4: =_xlfn.XLOOKUP(C4,customers!$A$1:$A$1001,customers!$G$1:$G$1001,,0) | I4: =INDEX(products!$A$1:$G$49,MATCH(orders!$D4,products!$A$1:$A$49,0),MATCH(orders!I$1,products!$A$1:$G$1,0)) | J4: =INDEX(products!$A$1:$G$49,MATCH(orders!$D4,products!$A$1:$A$49,0),MATCH(orders!J$1,products!$A$1:$G$1,0)) | K4: =INDEX(products!$A$1:$G$49,MATCH(orders!$D4,products!$A$1:$A$49,0),MATCH(orders!K$1,products!$A$1:$G$1,0)) | L4: =INDEX(products!$A$1:$G$49,MATCH(orders!$D4,products!$A$1:$A$49,0),MATCH(orders!L$1,products!$A$1:$G$1,0)) | M4: =L4*E4 | N4: =IF(I4="Rob","Robusta",IF(I4="Exc","Excelsa",IF(I4="Ara","Arabica",IF(I4="Lib","Liberica","")))) | O4: =IF(J4="M","Medium",IF(J4="L","Light",IF(J4="D","Dark",""))) | P4: =_xlfn.XLOOKUP(Orders[[#This Row],[Customer ID]],customers!$A$1:$A$1001,customers!$I$1:$I$1001,,0)
A5: O8601 | B5: 2025-07-12 | C5: O7867 | D5: O6609 | E5: 79 | F5: =_xlfn.XLOOKUP(C5,customers!$A$1:$A$1001,customers!$B$1:$B$1001,,0) | G5: =IF(_xlfn.XLOOKUP(C5,customers!$A$1:$A$1001,customers!$C$1:$C$1001,,0)=0,"",_xlfn.XLOOKUP(C5,customers!$A$1:$A$1001,customers!$C$1:$C$1001,,0)) | H5: =_xlfn.XLOOKUP(C5,customers!$A$1:$A$1001,customers!$G$1:$G$1001,,0) | I5: =INDEX(products!$A$1:$G$49,MATCH(orders!$D5,products!$A$1:$A$49,0),MATCH(orders!I$1,products!$A$1:$G$1,0)) | J5: =INDEX(products!$A$1:$G$49,MATCH(orders!$D5,products!$A$1:$A$49,0),MATCH(orders!J$1,products!$A$1:$G$1,0)) | K5: =INDEX(products!$A$1:$G$49,MATCH(orders!$D5,products!$A$1:$A$49,0),MATCH(orders!K$1,products!$A$1:$G$1,0)) | L5: =INDEX(products!$A$1:$G$49,MATCH(orders!$D5,products!$A$1:$A$49,0),MATCH(orders!L$1,products!$A$1:$G$1,0)) | M5: =L5*E5 | N5: =IF(I5="Rob","Robusta",IF(I5="Exc","Excelsa",IF(I5="Ara","Arabica",IF(I5="Lib","Liberica","")))) | O5: =IF(J5="M","Medium",IF(J5="L","Light",IF(J5="D","Dark",""))) | P5: =_xlfn.XLOOKUP(Orders[[#This Row],[Customer ID]],customers!$A$1:$A$1001,customers!$I$1:$I$1001,,0)
A6: O7007 | B6: 2024-06-05 | C6: O1432 | D6: O8803 | E6: 157 | F6: =_xlfn.XLOOKUP(C6,customers!$A$1:$A$1001,customers!$B$1:$B$1001,,0) | G6: =IF(_xlfn.XLOOKUP(C6,customers!$A$1:$A$1001,customers!$C$1:$C$1001,,0)=0,"",_xlfn.XLOOKUP(C6,customers!$A$1:$A$1001,customers!$C$1:$C$1001,,0)) | H6: =_xlfn.XLOOKUP(C6,customers!$A$1:$A$1001,customers!$G$1:$G$1001,,0) | I6: =INDEX(products!$A$1:$G$49,MATCH(orders!$D6,products!$A$1:$A$49,0),MATCH(orders!I$1,products!$A$1:$G$1,0)) | J6: =INDEX(products!$A$1:$G$49,MATCH(orders!$D6,products!$A$1:$A$49,0),MATCH(orders!J$1,products!$A$1:$G$1,0)) | K6: =INDEX(products!$A$1:$G$49,MATCH(orders!$D6,products!$A$1:$A$49,0),MATCH(orders!K$1,products!$A$1:$G$1,0)) | L6: =INDEX(products!$A$1:$G$49,MATCH(orders!$D6,products!$A$1:$A$49,0),MATCH(orders!L$1,products!$A$1:$G$1,0)) | M6: =L6*E6 | N6: =IF(I6="Rob","Robusta",IF(I6="Exc","Excelsa",IF(I6="Ara","Arabica",IF(I6="Lib","Liberica","")))) | O6: =IF(J6="M","Medium",IF(J6="L","Light",IF(J6="D","Dark",""))) | P6: =_xlfn.XLOOKUP(Orders[[#This Row],[Customer ID]],customers!$A$1:$A$1001,customers!$I$1:$I$1001,,0)
A7: O3562 | B7: 2022-12-31 | C7: O1139 | D7: O3683 | E7: 95 | F7: =_xlfn.XLOOKUP(C7,customers!$A$1:$A$1001,customers!$B$1:$B$1001,,0) | G7: =IF(_xlfn.XLOOKUP(C7,customers!$A$1:$A$1001,customers!$C$1:$C$1001,,0)=0,"",_xlfn.XLOOKUP(C7,customers!$A$1:$A$1001,customers!$C$1:$C$1001,,0)) | H7: =_xlfn.XLOOKUP(C7,customers!$A$1:$A$1001,customers!$G$1:$G$1001,,0) | I7: =INDEX(products!$A$1:$G$49,MATCH(orders!$D7,products!$A$1:$A$49,0),MATCH(orders!I$1,products!$A$1:$G$1,0)) | J7: =INDEX(products!$A$1:$G$49,MATCH(orders!$D7,products!$A$1:$A$49,0),MATCH(orders!J$1,products!$A$1:$G$1,0)) | K7: =INDEX(products!$A$1:$G$49,MATCH(orders!$D7,products!$A$1:$A$49,0),MATCH(orders!K$1,products!$A$1:$G$1,0)) | L7: =INDEX(products!$A$1:$G$49,MATCH(orders!$D7,products!$A$1:$A$49,0),MATCH(orders!L$1,products!$A$1:$G$1,0)) | M7: =L7*E7 | N7: =IF(I7="Rob","Robusta",IF(I7="Exc","Excelsa",IF(I7="Ara","Arabica",IF(I7="Lib","Liberica","")))) | O7: =IF(J7="M","Medium",IF(J7="L","Light",IF(J7="D","Dark",""))) | P7: =_xlfn.XLOOKUP(Orders[[#This Row],[Customer ID]],customers!$A$1:$A$1001,customers!$I$1:$I$1001,,0)
A8: O1622 | B8: 2020-05-22 | C8: O9643 | D8: O5137 | E8: 341 | F8: =_xlfn.XLOOKUP(C8,customers!$A$1:$A$1001,customers!$B$1:$B$1001,,0) | G8: =IF(_xlfn.XLOOKUP(C8,customers!$A$1:$A$1001,customers!$C$1:$C$1001,,0)=0,"",_xlfn.XLOOKUP(C8,customers!$A$1:$A$1001,customers!$C$1:$C$1001,,0)) | H8: =_xlfn.XLOOKUP(C8,customers!$A$1:$A$1001,customers!$G$1:$G$1001,,0) | I8: =INDEX(products!$A$1:$G$49,MATCH(orders!$D8,products!$A$1:$A$49,0),MATCH(orders!I$1,products!$A$1:$G$1,0)) | J8: =INDEX(products!$A$1:$G$49,MATCH(orders!$D8,products!$A$1:$A$49,0),MATCH(orders!J$1,products!$A$1:$G$1,0)) | K8: =INDEX(products!$A$1:$G$49,MATCH(orders!$D8,products!$A$1:$A$49,0),MATCH(orders!K$1,products!$A$1:$G$1,0)) | L8: =INDEX(products!$A$1:$G$49,MATCH(orders!$D8,products!$A$1:$A$49,0),MATCH(orders!L$1,products!$A$1:$G$1,0)) | M8: =L8*E8 | N8: =IF(I8="Rob","Robusta",IF(I8="Exc","Excelsa",IF(I8="Ara","Arabica",IF(I8="Lib","Liberica","")))) | O8: =IF(J8="M","Medium",IF(J8="L","Light",IF(J8="D","Dark",""))) | P8: =_xlfn.XLOOKUP(Orders[[#This Row],[Customer ID]],customers!$A$1:$A$1001,customers!$I$1:$I$1001,,0)
A9: O9014 | B9: 2023-01-13 | C9: O4854 | D9: O8268 | E9: 331 | F9: =_xlfn.XLOOKUP(C9,customers!$A$1:$A$1001,customers!$B$1:$B$1001,,0) | G9: =IF(_xlfn.XLOOKUP(C9,customers!$A$1:$A$1001,customers!$C$1:$C$1001,,0)=0,"",_xlfn.XLOOKUP(C9,customers!$A$1:$A$1001,customers!$C$1:$C$1001,,0)) | H9: =_xlfn.XLOOKUP(C9,customers!$A$1:$A$1001,customers!$G$1:$G$1001,,0) | I9: =INDEX(products!$A$1:$G$49,MATCH(orders!$D9,products!$A$1:$A$49,0),MATCH(orders!I$1,products!$A$1:$G$1,0)) | J9: =INDEX(products!$A$1:$G$49,MATCH(orders!$D9,products!$A$1:$A$49,0),MATCH(orders!J$1,products!$A$1:$G$1,0)) | K9: =INDEX(products!$A$1:$G$49,MATCH(orders!$D9,products!$A$1:$A$49,0),MATCH(orders!K$1,products!$A$1:$G$1,0)) | L9: =INDEX(products!$A$1:$G$49,MATCH(orders!$D9,products!$A$1:$A$49,0),MATCH(orders!L$1,products!$A$1:$G$1,0)) | M9: =L9*E9 | N9: =IF(I9="Rob","Robusta",IF(I9="Exc","Excelsa",IF(I9="Ara","Arabica",IF(I9="Lib","Liberica","")))) | O9: =IF(J9="M","Medium",IF(J9="L","Light",IF(J9="D","Dark",""))) | P9: =_xlfn.XLOOKUP(Orders[[#This Row],[Customer ID]],customers!$A$1:$A$1001,customers!$I$1:$I$1001,,0)
A10: O4021 | B10: 2020-01-02 | C10: O3688 | D10: O2479 | E10: 394 | F10: =_xlfn.XLOOKUP(C10,customers!$A$1:$A$1001,customers!$B$1:$B$1001,,0) | G10: =IF(_xlfn.XLOOKUP(C10,customers!$A$1:$A$1001,customers!$C$1:$C$1001,,0)=0,"",_xlfn.XLOOKUP(C10,customers!$A$1:$A$1001,customers!$C$1:$C$1001,,0)) | H10: =_xlfn.XLOOKUP(C10,customers!$A$1:$A$1001,customers!$G$1:$G$1001,,0) | I10: =INDEX(products!$A$1:$G$49,MATCH(orders!$D10,products!$A$1:$A$49,0),MATCH(orders!I$1,products!$A$1:$G$1,0)) | J10: =INDEX(products!$A$1:$G$49,MATCH(orders!$D10,products!$A$1:$A$49,0),MATCH(orders!J$1,products!$A$1:$G$1,0)) | K10: =INDEX(products!$A$1:$G$49,MATCH(orders!$D10,products!$A$1:$A$49,0),MATCH(orders!K$1,products!$A$1:$G$1,0)) | L10: =INDEX(products!$A$1:$G$49,MATCH(orders!$D10,products!$A$1:$A$49,0),MATCH(orders!L$1,products!$A$1:$G$1,0)) | M10: =L10*E10 | N10: =IF(I10="Rob","Robusta",IF(I10="Exc","Excelsa",IF(I10="Ara","Arabica",IF(I10="Lib","Liberica","")))) | O10: =IF(J10="M","Medium",IF(J10="L","Light",IF(J10="D","Dark",""))) | P10: =_xlfn.XLOOKUP(Orders[[#This Row],[Customer ID]],customers!$A$1:$A$1001,customers!$I$1:$I$1001,,0)
A11: O5477 | B11: 2022-05-21 | C11: O5119 | D11: O2906 | E11: 87 | F11: =_xlfn.XLOOKUP(C11,customers!$A$1:$A$1001,customers!$B$1:$B$1001,,0) | G11: =IF(_xlfn.XLOOKUP(C11,customers!$A$1:$A$1001,customers!$C$1:$C$1001,,0)=0,"",_xlfn.XLOOKUP(C11,customers!$A$1:$A$1001,customers!$C$1:$C$1001,,0)) | H11: =_xlfn.XLOOKUP(C11,customers!$A$1:$A$1001,customers!$G$1:$G$1001,,0) | I11: =INDEX(products!$A$1:$G$49,MATCH(orders!$D11,products!$A$1:$A$49,0),MATCH(orders!I$1,products!$A$1:$G$1,0)) | J11: =INDEX(products!$A$1:$G$49,MATCH(orders!$D11,products!$A$1:$A$49,0),MATCH(orders!J$1,products!$A$1:$G$1,0)) | K11: =INDEX(products!$A$1:$G$49,MATCH(orders!$D11,products!$A$1:$A$49,0),MATCH(orders!K$1,products!$A$1:$G$1,0)) | L11: =INDEX(products!$A$1:$G$49,MATCH(orders!$D11,products!$A$1:$A$49,0),MATCH(orders!L$1,products!$A$1:$G$1,0)) | M11: =L11*E11 | N11: =IF(I11="Rob","Robusta",IF(I11="Exc","Excelsa",IF(I11="Ara","Arabica",IF(I11="Lib","Liberica","")))) | O11: =IF(J11="M","Medium",IF(J11="L","Light",IF(J11="D","Dark",""))) | P11: =_xlfn.XLOOKUP(Orders[[#This Row],[Customer ID]],customers!$A$1:$A$1001,customers!$I$1:$I$1001,,0)
A12: O3513 | B12: 2022-07-24 | C12: O9439 | D12: O8071 | E12: 484 | F12: =_xlfn.XLOOKUP(C12,customers!$A$1:$A$1001,customers!$B$1:$B$1001,,0) | G12: =IF(_xlfn.XLOOKUP(C12,customers!$A$1:$A$1001,customers!$C$1:$C$1001,,0)=0,"",_xlfn.XLOOKUP(C12,customers!$A$1:$A$1001,customers!$C$1:$C$1001,,0)) | H12: =_xlfn.XLOOKUP(C12,customers!$A$1:$A$1001,customers!$G$1:$G$1001,,0) | I12: =INDEX(products!$A$1:$G$49,MATCH(orders!$D12,products!$A$1:$A$49,0),MATCH(orders!I$1,products!$A$1:$G$1,0)) | J12: =INDEX(products!$A$1:$G$49,MATCH(orders!$D12,products!$A$1:$A$49,0),MATCH(orders!J$1,products!$A$1:$G$1,0)) | K12: =INDEX(products!$A$1:$G$49,MATCH(orders!$D12,products!$A$1:$A$49,0),MATCH(orders!K$1,products!$A$1:$G$1,0)) | L12: =INDEX(products!$A$1:$G$49,MATCH(orders!$D12,products!$A$1:$A$49,0),MATCH(orders!L$1,products!$A$1:$G$1,0)) | M12: =L12*E12 | N12: =IF(I12="Rob","Robusta",IF(I12="Exc","Excelsa",IF(I12="Ara","Arabica",IF(I12="Lib","Liberica","")))) | O12: =IF(J12="M","Medium",IF(J12="L","Light",IF(J12="D","Dark",""))) | P12: =_xlfn.XLOOKUP(Orders[[#This Row],[Customer ID]],customers!$A$1:$A$1001,customers!$I$1:$I$1001,,0)
A13: O2983 | B13: 2020-10-21 | C13: O4818 | D13: O8291 | E13: 312 | F13: =_xlfn.XLOOKUP(C13,customers!$A$1:$A$1001,customers!$B$1:$B$1001,,0) | G13: =IF(_xlfn.XLOOKUP(C13,customers!$A$1:$A$1001,customers!$C$1:$C$1001,,0)=0,"",_xlfn.XLOOKUP(C13,customers!$A$1:$A$1001,customers!$C$1:$C$1001,,0)) | H13: =_xlfn.XLOOKUP(C13,customers!$A$1:$A$1001,customers!$G$1:$G$1001,,0) | I13: =INDEX(products!$A$1:$G$49,MATCH(orders!$D13,products!$A$1:$A$49,0),MATCH(orders!I$1,products!$A$1:$G$1,0)) | J13: =INDEX(products!$A$1:$G$49,MATCH(orders!$D13,products!$A$1:$A$49,0),MATCH(orders!J$1,products!$A$1:$G$1,0)) | K13: =INDEX(products!$A$1:$G$49,MATCH(orders!$D13,products!$A$1:$A$49,0),MATCH(orders!K$1,products!$A$1:$G$1,0)) | L13: =INDEX(products!$A$1:$G$49,MATCH(orders!$D13,products!$A$1:$A$49,0),MATCH(orders!L$1,products!$A$1:$G$1,0)) | M13: =L13*E13 | N13: =IF(I13="Rob","Robusta",IF(I13="Exc","Excelsa",IF(I13="Ara","Arabica",IF(I13="Lib","Liberica","")))) | O13: =IF(J13="M","Medium",IF(J13="L","Light",IF(J13="D","Dark",""))) | P13: =_xlfn.XLOOKUP(Orders[[#This Row],[Customer ID]],customers!$A$1:$A$1001,customers!$I$1:$I$1001,,0)
... A1001: O2697 | B1001: 2025-04-15 | C1001: O3637 | D1001: O1270 | E1001: 419 | F1001: =_xlfn.XLOOKUP(C1001,customers!$A$1:$A$1001,customers!$B$1:$B$1001,,0) | G1001: =IF(_xlfn.XLOOKUP(C1001,customers!$A$1:$A$1001,customers!$C$1:$C$1001,,0)=0,"",_xlfn.XLOOKUP(C1001,customers!$A$1:$A$1001,customers!$C$1:$C$1001,,0)) | H1001: =_xlfn.XLOOKUP(C1001,customers!$A$1:$A$1001,customers!$G$1:$G$1001,,0) | I1001: =INDEX(products!$A$1:$G$49,MATCH(orders!$D1001,products!$A$1:$A$49,0),MATCH(orders!I$1,products!$A$1:$G$1,0)) | J1001: =INDEX(products!$A$1:$G$49,MATCH(orders!$D1001,products!$A$1:$A$49,0),MATCH(orders!J$1,products!$A$1:$G$1,0)) | K1001: =INDEX(products!$A$1:$G$49,MATCH(orders!$D1001,products!$A$1:$A$49,0),MATCH(orders!K$1,products!$A$1:$G$1,0)) | L1001: =INDEX(products!$A$1:$G$49,MATCH(orders!$D1001,products!$A$1:$A$49,0),MATCH(orders!L$1,products!$A$1:$G$1,0)) | M1001: =L1001*E1001 | N1001: =IF(I1001="Rob","Robusta",IF(I1001="Exc","Excelsa",IF(I1001="Ara","Arabica",IF(I1001="Lib","Liberica","")))) | O1001: =IF(J1001="M","Medium",IF(J1001="L","Light",IF(J1001="D","Dark",""))) | P1001: =_xlfn.XLOOKUP(Orders[[#This Row],[Customer ID]],customers!$A$1:$A$1001,customers!$I$1:$I$1001,,0)

Sheet customers
A1: Customer ID | B1: Customer Name | C1: Email | D1: Phone Number | E1: Address Line 1 | F1: City | G1: Country | H1: Postcode | I1: Loyalty Card
A2: C7285 | B2: Brandon Brown | C2: hahnkaren@yahoo.com | D2: +1-914-306-3083x7520 | E2: Unit 5751 Box 3600, DPO AE 34456 | F2: Emilyview | G2: Afghanistan | H2: land | I2: a
A3: C7188 | B3: Brianna Williams | C3: payneholly@dennis.org | D3: 060-786-2159x36453 | E3: 946 Hill Freeway Suite 073, North Kelly, SC 43833 | F3: Hayesview | G3: Bouvet Island (Bouvetoya) | H3: any | I3: still
A4: C3307 | B4: Christopher Hall | C4: hjones@russell.biz | D4: +1-689-057-8384x5753 | E4: 30923 Heather Motorway Suite 807, New Jasonberg, AR 91464 | F4: Michaelside | G4: Trinidad and Tobago | H4: fact | I4: deep
A5: C5820 | B5: Anthony Harrison | C5: yvonne84@yahoo.com | D5: 391.955.9048x1041 | E5: 1473 Lawrence Stream Apt. 491, North Brandonport, VT 90560 | F5: Wallacemouth | G5: Armenia | H5: particularly | I5: guy
A6: C5338 | B6: Deanna Bartlett | C6: john76@gmail.com | D6: 263.086.7928x2743 | E6: 8775 Johnson Springs Apt. 088, Garrettstad, CA 96776 | F6: East Brian | G6: Iraq | H6: still | I6: attack
A7: C4818 | B7: Richard Nicholson | C7: johnsonbryce@lynch-torres.info | D7: 251.224.4515x32191 | E7: 275 Espinoza Keys, Lambport, OK 28884 | F7: Shellyview | G7: Guadeloupe | H7: also | I7: ago
A8: C5389 | B8: Jennifer Terrell | C8: stoutmichelle@bryant-best.biz | D8: 7152615493 | E8: 678 Ashley Mission, East Kimberlyshire, SC 67488 | F8: Alexandriastad | G8: Falkland Islands (Malvinas) | H8: yet | I8: material
A9: C1307 | B9: Judith Hart | C9: joshua02@white.com | D9: 690-165-2704x11745 | E9: 3847 Johnson Stream Apt. 796, West Pamelaborough, RI 91872 | F9: New Jessicaport | G9: Belarus | H9: modern | I9: rate
A10: C4021 | B10: Alan Kelly | C10: awells@gmail.com | D10: 511.150.0381 | E10: 95333 Hopkins Stream Apt. 418, Jeffreychester, AZ 26832 | F10: East Emily | G10: Fiji | H10: face | I10: science
A11: C4569 | B11: Robin Jenkins | C11: lindsey30@hotmail.com | D11: 611.852.3274 | E11: 53384 Donovan Mission Apt. 023, Carlchester, AK 96303 | F11: Higginsville | G11: Poland | H11: cup | I11: garden
A12: C2678 | B12: Barbara Chavez | C12: onelson@wiley.com | D12: (730)252-5614 | E12: 9630 Seth Walk, Ramirezside, NC 63686 | F12: North Brenda | G12: Sierra Leone | H12: parent | I12: change
... A1001: C2313 | B1001: Katelyn Lee | C1001: hooverjeremy@bennett-black.com | D1001: 691-027-3499x2354 | E1001: 45396 Angela Field Suite 545, West James, TX 08078 | F1001: East Ethan | G1001: Bahamas | H1001: condition | I1001: information

Sheet products
A1: Product ID | B1: Coffee Type | C1: Roast Type | D1: Size | E1: Unit Price | F1: Price per 100g | G1: Profit
A2: P5186 | B2: quality | C2: beyond | D2: up | E2: 3478.82 | F2: 1408.57 | G2: add
A3: P7105 | B3: wife | C3: hour | D3: scientist | E3: 1087.61 | F3: 1987.41 | G3: suffer
A4: P3423 | B4: together | C4: could | D4: reality | E4: 950.52 | F4: 4687.27 | G4: return
A5: P7064 | B5: well | C5: agreement | D5: cut | E5: 2881.96 | F5: 1568.32 | G5: into
A6: P7089 | B6: role | C6: a | D6: individual | E6: 2796.08 | F6: 548.9 | G6: pressure
A7: P3947 | B7: else | C7: base | D7: work | E7: 2341.9 | F7: 237.47 | G7: guy
A8: P8852 | B8: piece | C8: give | D8: letter | E8: 368.52 | F8: 2094.09 | G8: particularly
A9: P5347 | B9: into | C9: early | D9: size | E9: 3382.86 | F9: 1676.72 | G9: forward
A10: P3565 | B10: short | C10: door | D10: look | E10: 1871.23 | F10: 4210.5 | G10: outside
A11: P1430 | B11: back | C11: example | D11: member | E11: 1391.68 | F11: 3356.2 | G11: behavior
A12: P7609 | B12: their | C12: those | D12: keep | E12: 3404.84 | F12: 3285.29 | G12: notice
A13: P4231 | B13: lose | C13: film | D13: budget | E13: 678.16 | F13: 1344.91 | G13: pressure
... A49: P2769 | B49: game | C49: find | D49: place | E49: 4544.22 | F49: 3029.69 | G49: join
